Workbook

Sheet Detail1
A1: Details for Sum of Profit - Product_Category: Accessories
A3: Transaction_ID | B3: Date | C3: Store_ID | D3: State | E3: Channel | F3: Product_Category | G3: Product | H3: Customer_ID | I3: Customer_Type | J3: Units | K3: Unit_Price_NGN | L3: Discount_Pct | M3: Revenue_Reported_NGN | N3: Cost_Per_Unit_NGN | O3: Return_Flag | P3: Sales_Rep | Q3: Corrected Revenue | R3: Profit | S3: s
A4: 100186 | B4: 46041 | C4: AB-02 | D4: Abuja | E4: Online | F4: Accessories | G4: Phone Case | H4: C1014 | I4: New | J4: 2 | K4: 9000 | L4: 0.05 | M4: 17100 | N4: 3500 | O4: No | P4: Grace | Q4: 17100 | R4: 10100
A5: 100116 | B5: 46056 | C5: PH-01 | D5: Port Harcourt | E5: In-store | F5: Accessories | G5: Backpack | H5: C1190 | I5: Returning | J5: 5 | K5: 28000 | L5: 0 | M5: 140000 | N5: 16000 | O5: No | P5: Kemi | Q5: 140000 | R5: 60000

Sheet Sheet3
A3: Row Labels | B3: Sum of Profit | K3: Row Labels | L3: Count of Transaction_ID | V3: Row Labels | W3: Average of Profit_Margin | AI3: Row Labels | AJ3: Sum of Corrected Revenue
A4: Abuja | B4: 1698100 | K4: No | L4: 384 | V4: 0 | W4: 0.40604913 | AI4: Jan | AJ4: 6722250
A5: Ibadan | B5: 2730325 | K5: Accessories | L5: 104 | V5: 0.05 | W5: 0.40257022 | AI5: Feb | AJ5: 5364300
A6: Kano | B6: 3243600 | K6: Electronics | L6: 156 | V6: 0.1 | W6: 0.36105089 | AI6: Mar | AJ6: 6298725
A7: Lagos | B7: 4579900 | K7: Home | L7: 124 | V7: 0.15 | W7: 0.33458821 | AI7: Apr | AJ7: 6343000
A8: Port Harcourt | B8: 2338500 | K8: Yes | L8: 36 | V8: 0.2 | W8: 0.2338285 | AI8: May | AJ8: 7008500
A9: Grand Total | B9: 14590425 | K9: Accessories | L9: 5 | V9: 0.25 | W9: 0.23419324 | AI9: Jun | AJ9: 5397250
K10: Electronics | L10: 21 | V10: Grand Total | W10: 0.36867966 | AI10: Jul | AJ10: 6378275
K11: Home | L11: 10 | AI11: Aug | AJ11: 3167425
K12: Grand Total | L12: 420 | AI12: Grand Total | AJ12: 46679725
A19: Row Labels | B19: Sum of Profit
A20: Accessories | B20: 1929625 | J20: Row Labels | K20: Sum of Profit | T20: Row Labels | U20: Count of Return_Flag | AD20: Row Labels | AE20: Sum of Profit
A21: Electronics | B21: 8986500 | J21: 0 | K21: 5638000 | T21: No | U21: 384 | AD21: Abuja | AE21: 1698100
A22: Home | B22: 3674300 | J22: 0.05 | K22: 4133300 | T22: In-store | U22: 189 | AD22: Ibadan | AE22: 2730325
A23: Grand Total | B23: 14590425 | J23: 0.1 | K23: 2827200 | T23: Online | U23: 121 | AD23: Kano | AE23: 3243600
J24: 0.15 | K24: 1516625 | T24: WhatsApp | U24: 74 | AD24: Lagos | AE24: 4579900 | AO24: Discount | AP24: Profit_Margin
J25: 0.2 | K25: 158700 | T25: Yes | U25: 36 | AD25: Port Harcourt | AE25: 2338500 | AO25: 0 | AP25: =SUMIFS(Cleaned_data!$R:$R,Cleaned_data!$L:$L,AO25)/SUMIFS(Cleaned_data!$Q:$Q,Cleaned_data!$L:$L,AO25) -> 0.35689191
J26: 0.25 | K26: 316600 | T26: In-store | U26: 13 | AD26: Grand Total | AE26: 14590425 | AO26: 0.05 | AP26: =SUMIFS(Cleaned_data!$R:$R,Cleaned_data!$L:$L,AO26)/SUMIFS(Cleaned_data!$Q:$Q,Cleaned_data!$L:$L,AO26) -> 0.33005933
J27: Grand Total | K27: 14590425 | T27: Online | U27: 13 | AO27: 0.1 | AP27: =SUMIFS(Cleaned_data!$R:$R,Cleaned_data!$L:$L,AO27)/SUMIFS(Cleaned_data!$Q:$Q,Cleaned_data!$L:$L,AO27) -> 0.28448952
T28: WhatsApp | U28: 10 | AO28: 0.15 | AP28: =SUMIFS(Cleaned_data!$R:$R,Cleaned_data!$L:$L,AO28)/SUMIFS(Cleaned_data!$Q:$Q,Cleaned_data!$L:$L,AO28) -> 0.2713917
T29: Grand Total | U29: 420 | AO29: 0.2 | AP29: =SUMIFS(Cleaned_data!$R:$R,Cleaned_data!$L:$L,AO29)/SUMIFS(Cleaned_data!$Q:$Q,Cleaned_data!$L:$L,AO29) -> 0.20794025
AO30: 0.25 | AP30: =SUMIFS(Cleaned_data!$R:$R,Cleaned_data!$L:$L,AO30)/SUMIFS(Cleaned_data!$Q:$Q,Cleaned_data!$L:$L,AO30) -> 0.15294686
AO35: Discount | AP35: Average Profit Margin
AO36: 0 | AP36: 0.417
AO37: 0.05 | AP37: 0.39
T38: Row Labels | U38: Sum of Corrected Revenue | AO38: 0.1 | AP38: 0.364
T39: Jan | U39: 6722250 | AO39: 0.15 | AP39: 0.333
D40: Row Labels | E40: Sum of Profit | T40: Feb | U40: 5364300 | AO40: 0.2 | AP40: 0.208
D41: Accessories | E41: 1929625 | T41: Mar | U41: 6298725 | AO41: 0.25 | AP41: 0.163
D42: Electronics | E42: 8986500 | T42: Apr | U42: 6343000
D43: Home | E43: 3674300 | T43: May | U43: 7008500
D44: Grand Total | E44: 14590425 | T44: Jun | U44: 5397250
T45: Jul | U45: 6378275
T46: Aug | U46: 3167425
T47: Grand Total | U47: 46679725
A63: Row Labels | B63: Count of Return_Flag
A64: No | B64: 384
A65: In-store | B65: 189
A66: Online | B66: 121
A67: WhatsApp | B67: 74 | Q67: Channel | R67: Return Rate
...

Sheet Dashboard
A1: {=A1=A1:EB273} -> 0
C9: z
BL177: z

Sheet Sheet1

Sheet Cleaned_data
A1: Transaction_ID | B1: Date | C1: Store_ID | D1: State | E1: Channel | F1: Product_Category | G1: Product | H1: Customer_ID | I1: Customer_Type | J1: Units | K1: Unit_Price_NGN | L1: Discount_Pct | M1: Revenue_Reported_NGN | N1: Cost_Per_Unit_NGN | O1: Return_Flag | P1: Sales_Rep | Q1: Corrected Revenue | R1: Profit | S1: Revenue_Check | T1: Profit_Margin
A2: 100001 | B2: 46167 | C2: AB-02 | D2: Abuja | E2: WhatsApp | F2: Home | G2: Standing Fan | H2: C1141 | I2: New | J2: 1 | K2: 58000 | L2: 0 | M2: 58000 | N2: 39000 | O2: No | P2: Chinedu | Q2: =J2*K2*(1-L2) -> 58000 | R2: =Q2-(J2*N2) -> 19000 | S2: =IF(M2=Q2,"Match","Mismatch") -> Match | T2: =R2/Q2 -> 0.32758621
A3: 100002 | B3: 46129 | C3: LG-01 | D3: Lagos | E3: WhatsApp | F3: Electronics | G3: Smartphone | H3: C1083 | I3: Returning | J3: 5 | K3: 165000 | L3: 0.05 | M3: 627000 | N3: 112000 | O3: No | P3: Kemi | Q3: =J3*K3*(1-L3) -> 783750 | R3: =Q3-(J3*N3) -> 223750 | S3: =IF(M3=Q3,"Match","Mismatch") -> Mismatch | T3: =R3/Q3 -> 0.28548644
A4: 100003 | B4: 46079 | C4: AB-01 | D4: Abuja | E4: WhatsApp | F4: Electronics | G4: Earbuds | H4: C1029 | I4: Returning | J4: 3 | K4: 32000 | L4: 0.2 | M4: 76800 | N4: 19000 | O4: No | P4: Chinedu | Q4: =J4*K4*(1-L4) -> 76800 | R4: =Q4-(J4*N4) -> 19800 | S4: =IF(M4=Q4,"Match","Mismatch") -> Match | T4: =R4/Q4 -> 0.2578125
A5: 100004 | B5: 46182 | C5: KN-01 | D5: Kano | E5: Online | F5: Electronics | G5: Power Bank | H5: C1082 | I5: Returning | J5: 4 | K5: 26000 | L5: 0 | M5: 104000 | N5: 15000 | O5: No | P5: Grace | Q5: =J5*K5*(1-L5) -> 104000 | R5: =Q5-(J5*N5) -> 44000 | S5: =IF(M5=Q5,"Match","Mismatch") -> Match | T5: =R5/Q5 -> 0.42307692
A6: 100005 | B6: 46172 | C6: LG-01 | D6: Lagos | E6: Online | F6: Electronics | G6: Smartphone | H6: C1180 | I6: Returning | J6: 1 | K6: 165000 | L6: 0.05 | M6: 156750 | N6: 112000 | O6: No | P6: Chinedu | Q6: =J6*K6*(1-L6) -> 156750 | R6: =Q6-(J6*N6) -> 44750 | S6: =IF(M6=Q6,"Match","Mismatch") -> Match | T6: =R6/Q6 -> 0.28548644
A7: 100006 | B7: 46238 | C7: LG-02 | D7: Lagos | E7: In-store | F7: Accessories | G7: USB Cable | H7: C1161 | I7: Returning | J7: 3 | K7: 6500 | L7: 0.1 | M7: 17550 | N7: 2200 | O7: No | P7: Bola | Q7: =J7*K7*(1-L7) -> 17550 | R7: =Q7-(J7*N7) -> 10950 | S7: =IF(M7=Q7,"Match","Mismatch") -> Match | T7: =R7/Q7 -> 0.62393162
A8: 100007 | B8: 46090 | C8: LG-01 | D8: Lagos | E8: In-store | F8: Electronics | G8: Power Bank | H8: C1007 | I8: New | J8: 3 | K8: 26000 | L8: 0.1 | M8: 70200 | N8: 15000 | O8: No | P8: Chinedu | Q8: =J8*K8*(1-L8) -> 70200 | R8: =Q8-(J8*N8) -> 25200 | S8: =IF(M8=Q8,"Match","Mismatch") -> Match | T8: =R8/Q8 -> 0.35897436
A9: 100008 | B9: 46229 | C9: KN-01 | D9: Kano | E9: Online | F9: Electronics | G9: Smartphone | H9: C1051 | I9: Returning | J9: 5 | K9: 165000 | L9: 0.05 | M9: 783750 | N9: 112000 | O9: No | P9: Kemi | Q9: =J9*K9*(1-L9) -> 783750 | R9: =Q9-(J9*N9) -> 223750 | S9: =IF(M9=Q9,"Match","Mismatch") -> Match | T9: =R9/Q9 -> 0.28548644
A10: 100009 | B10: 46028 | C10: IB-01 | D10: Ibadan | E10: In-store | F10: Home | G10: Blender | H10: C1111 | I10: Returning | J10: 3 | K10: 42000 | L10: 0.15 | M10: 107100 | N10: 28000 | O10: No | P10: Fatima | Q10: =J10*K10*(1-L10) -> 107100 | R10: =Q10-(J10*N10) -> 23100 | S10: =IF(M10=Q10,"Match","Mismatch") -> Match | T10: =R10/Q10 -> 0.21568627
A11: 100010 | B11: 46248 | C11: PH-01 | D11: Port Harcourt | E11: In-store | F11: Electronics | G11: Smartphone | H11: C1153 | I11: Returning | J11: 1 | K11: 165000 | L11: 0 | M11: 165000 | N11: 112000 | O11: No | P11: David | Q11: =J11*K11*(1-L11) -> 165000 | R11: =Q11-(J11*N11) -> 53000 | S11: =IF(M11=Q11,"Match","Mismatch") -> Match | T11: =R11/Q11 -> 0.32121212
A12: 100011 | B12: 46200 | C12: LG-01 | D12: Lagos | E12: In-store | F12: Electronics | G12: Earbuds | H12: C1059 | I12: Returning | J12: 1 | K12: 32000 | L12: 0 | M12: 32000 | N12: 19000 | O12: No | P12: David | Q12: =J12*K12*(1-L12) -> 32000 | R12: =Q12-(J12*N12) -> 13000 | S12: =IF(M12=Q12,"Match","Mismatch") -> Match | T12: =R12/Q12 -> 0.40625
A13: 100012 | B13: 46120 | C13: KN-01 | D13: Kano | E13: Online | F13: Accessories | G13: Phone Case | H13: C1028 | I13: New | J13: 1 | K13: 9000 | L13: 0 | M13: 9000 | N13: 3500 | O13: No | P13: David | Q13: =J13*K13*(1-L13) -> 9000 | R13: =Q13-(J13*N13) -> 5500 | S13: =IF(M13=Q13,"Match","Mismatch") -> Match | T13: =R13/Q13 -> 0.61111111
... A421: 100420 | B421: 46079 | C421: KN-01 | D421: Kano | E421: WhatsApp | F421: Electronics | G421: Smartphone | H421: C1089 | I421: Returning | J421: 2 | K421: 165000 | L421: 0.05 | M421: 313500 | N421: 112000 | O421: No | P421: Ibrahim | Q421: =J421*K421*(1-L421) -> 313500 | R421: =Q421-(J421*N421) -> 89500 | S421: =IF(M421=Q421,"Match","Mismatch") -> Match | T421: =R421/Q421 -> 0.28548644

Sheet Duplicate Check
A1: Transaction_ID | B1: Date | C1: Store_ID | D1: State | E1: Channel | F1: Product_Category | G1: Product | H1: Customer_ID | I1: Customer_Type | J1: Units | K1: Unit_Price_NGN | L1: Discount_Pct | M1: Revenue_Reported_NGN | N1: Cost_Per_Unit_NGN | O1: Return_Flag | P1: Sales_Rep
A2: 100001 | B2: 46167 | C2: AB-02 | D2: Abuja | E2: WhatsApp | F2: Home | G2: Standing Fan | H2: C1141 | I2: New | J2: 1 | K2: 58000 | L2: 0 | M2: 58000 | O2: No | P2: Chinedu
A3: 100002 | B3: 46129 | C3: LG-01 | D3: Lagos | E3: WhatsApp | F3: Electronics | G3: Smartphone | H3: C1083 | I3: Returning | J3: 5 | K3: 165000 | L3: 0.05 | M3: 627000 | N3: 112000 | O3: No | P3: Kemi
A4: 100003 | B4: 46079 | C4: AB-01 | D4: Abuja | E4: WhatsApp | F4: Electronics | G4: Earbuds | H4: C1029 | I4: Returning | J4: 3 | K4: 32000 | L4: 0.2 | M4: 76800 | N4: 19000 | O4: No | P4: Chinedu
A5: 100004 | B5: 46182 | C5: KN-01 | D5: Kano | E5: Online | F5: Electronics | G5: Power Bank | H5: C1082 | I5: Returning | J5: 4 | K5: 26000 | L5: 0 | M5: 104000 | N5: 15000 | O5: No | P5: Grace
A6: 100005 | B6: 46172 | C6: LG-01 | D6: Lagos | E6: Online | F6: Electronics | G6: Smartphone | H6: C1180 | I6: Returning | J6: 1 | K6: 165000 | L6: 0.05 | M6: 156750 | N6: 112000 | O6: No | P6: Chinedu
A7: 100006 | B7: 46238 | C7: LG-02 | D7: Lagos | E7: In-store | F7: Accessories | G7: USB Cable | H7: C1161 | I7: Returning | J7: 3 | K7: 6500 | L7: 0.1 | M7: 17550 | N7: 2200 | O7: No | P7: Bola
A8: 100007 | B8: 46090 | C8: LG-01 | D8: Lagos | E8: In-store | F8: Electronics | G8: Power Bank | H8: C1007 | I8: New | J8: 3 | K8: 26000 | L8: 0.1 | M8: 70200 | N8: 15000 | O8: No | P8: Chinedu
A9: 100008 | B9: 46229 | C9: KN-01 | D9: Kano | E9: Online | F9: Electronics | G9: Smartphone | H9: C1051 | I9: Returning | J9: 5 | K9: 165000 | L9: 0.05 | M9: 783750 | N9: 112000 | O9: No | P9: Kemi
A10: 100009 | B10: 46028 | C10: IB-01 | D10: Ibadan | E10: In-store | F10: Home | G10: Blender | H10: C1111 | I10: Returning | J10: 3 | K10: 42000 | L10: 0.15 | M10: 107100 | N10: 28000 | O10: No | P10: Fatima
A11: 100010 | B11: 46248 | C11: PH-01 | D11: Port Harcourt | E11: In-store | F11: Electronics | G11: Smartphone | H11: C1153 | I11: Returning | J11: 1 | K11: 165000 | L11: 0 | M11: 165000 | N11: 112000 | O11: No | P11: David
A12: 100011 | B12: 46200 | C12: LG-01 | D12: Lagos | E12: In-store | F12: Electronics | G12: Earbuds | H12: C1059 | I12: Returning | J12: 1 | K12: 32000 | L12: 0 | M12: 32000 | N12: 19000 | O12: No | P12: David
A13: 100012 | B13: 46120 | C13: KN-01 | D13: Kano | E13: Online | F13: Accessories | G13: Phone Case | H13: C1028 | I13: New | J13: 1 | K13: 9000 | L13: 0 | M13: 9000 | N13: 3500 | O13: No | P13: David
A14: 100013 | B14: 46153 | C14: IB-01 | D14: Ibadan | E14: In-store | F14: Home | G14: Electric Kettle | H14: C1192 | I14: New | J14: 2 | K14: 24000 | L14: 0 | M14: 48000 | N14: 15000 | O14: No | P14: Ibrahim
A15: 100014 | B15: 46195 | C15: AB-02 | D15: Abuja | E15: WhatsApp | F15: Accessories | G15: Backpack | H15: C1022 | I15: Returning | J15: 2 | K15: 28000 | L15: 0.25 | M15: 42000 | O15: No | P15: Fatima
A16: 100015 | B16: 46031 | C16: PH-01 | D16: Port Harcourt | E16: In-store | F16: Electronics | G16: Smartphone | H16: C1084 | I16: New | J16: 2 | K16: 165000 | L16: 0 | M16: 330000 | N16: 112000 | O16: No | P16: Grace
A17: 100016 | B17: 46228 | C17: LG-02 | D17: Lagos | E17: Online | F17: Accessories | G17: USB Cable | H17: C1123 | I17: New | J17: 1 | K17: 6500 | L17: 0.1 | M17: 4680 | N17: 2200 | O17: No | P17: Kemi
A18: 100017 | B18: 46032 | C18: KN-01 | D18: Kano | E18: WhatsApp | F18: Home | G18: Blender | H18: C1134 | I18: New | J18: 2 | K18: 42000 | L18: 0 | M18: 84000 | N18: 28000 | O18: No | P18: Ibrahim
A19: 100018 | B19: 46141 | C19: PH-01 | D19: Port Harcourt | E19: In-store | F19: Accessories | G19: USB Cable | H19: C1100 | I19: Returning | J19: 22 | K19: 6500 | L19: 0.15 | M19: 121550 | N19: 2200 | O19: No | P19: Kemi
A20: 100019 | B20: 46148 | C20: LG-01 | D20: Lagos | E20: In-store | F20: Electronics | G20: Power Bank | H20: C1189 | I20: Returning | J20: 1 | K20: 26000 | L20: 0.15 | M20: 22100 | N20: 15000 | O20: No | P20: Bola
A21: 100020 | B21: 46131 | C21: AB-02 | D21: Abuja | E21: In-store | F21: Electronics | G21: Power Bank | H21: C1050 | I21: Returning | J21: 1 | K21: 26000 | L21: 0.25 | M21: 19500 | O21: No | P21: Ibrahim
A22: 100021 | B22: 46148 | C22: AB-02 | D22: Abuja | E22: WhatsApp | F22: Electronics | G22: Power Bank | H22: C1184 | I22: New | J22: 1 | K22: 26000 | L22: 0 | M22: 26000 | N22: 15000 | O22: No | P22: Kemi
A23: 100022 | B23: 46033 | C23: IB-01 | D23: Ibadan | E23: WhatsApp | F23: Accessories | G23: Backpack | H23: C1022 | I23: New | J23: 1 | K23: 28000 | L23: 0.05 | M23: 26600 | N23: 16000 | O23: No | P23: Bola
A24: 100023 | B24: 46052 | C24: AB-01 | D24: Abuja | E24: Online | F24: Electronics | G24: Earbuds | H24: C1004 | I24: Returning | J24: 1 | K24: 32000 | L24: 0.15 | M24: 27200 | N24: 19000 | O24: No | P24: David
A25: 100024 | B25: 46150 | C25: AB-01 | D25: Abuja | E25: In-store | F25: Home | G25: Standing Fan | H25: C1034 | I25: New | J25: 2 | K25: 58000 | L25: 0.2 | M25: 92800 | O25: Yes | P25: Grace
A26: 100025 | B26: 46027 | C26: KN-01 | D26: Kano | E26: In-store | F26: Home | G26: Standing Fan | H26: C1164 | I26: Returning | J26: 5 | K26: 58000 | L26: 0.05 | M26: 275500 | N26: 39000 | O26: No | P26: David
A27: 100026 | B27: 46203 | C27: IB-01 | D27: Ibadan | E27: In-store | F27: Accessories | G27: Phone Case | H27: C1155 | I27: Returning | J27: 2 | K27: 9000 | L27: 0.1 | M27: 16200 | O27: No | P27: Chinedu
A28: 100027 | B28: 46142 | C28: KN-01 | D28: Kano | E28: WhatsApp | F28: Home | G28: Standing Fan | H28: C1073 | I28: New | J28: 4 | K28: 58000 | L28: 0.05 | M28: 220400 | N28: 39000 | O28: No | P28: David
A29: 100028 | B29: 46156 | C29: AB-01 | D29: Abuja | E29: Online | F29: Electronics | G29: Power Bank | H29: C1136 | I29: Returning | J29: 22 | K29: 26000 | L29: 0.25 | M29: 429000 | N29: 15000 | O29: No | P29: Bola
A30: 100029 | B30: 46103 | C30: AB-01 | D30: Abuja | E30: In-store | F30: Home | G30: Standing Fan | H30: C1173 | I30: Returning | J30: 5 | K30: 58000 | L30: 0.1 | M30: 261000 | O30: No | P30: Chinedu
A31: 100030 | B31: 46209 | C31: KN-01 | D31: Kano | E31: Online | F31: Electronics | G31: Power Bank | H31: C1071 | I31: New | J31: 1 | K31: 26000 | L31: 0.05 | M31: 24700 | N31: 15000 | O31: No | P31: David
A32: 100031 | B32: 46182 | C32: AB-01 | D32: Abuja | E32: In-store | F32: Home | G32: Standing Fan | H32: C1047 | I32: New | J32: 2 | K32: 58000 | L32: 0.15 | M32: 98600 | N32: 39000 | O32: No | P32: Aisha
A33: 100032 | B33: 46109 | C33: PH-01 | D33: Port Harcourt | E33: Online | F33: Home | G33: Electric Kettle | H33: C1051 | I33: New | J33: 1 | K33: 24000 | L33: 0.05 | M33: 22800 | N33: 15000 | O33: No | P33: Kemi
A34: 100033 | B34: 46152 | C34: LG-01 | D34: Lagos | E34: In-store | F34: Home | G34: Standing Fan | H34: C1094 | I34: New | J34: 3 | K34: 58000 | L34: 0 | M34: 174000 | N34: 39000 | O34: No | P34: Aisha
A35: 100034 | B35: 46157 | C35: PH-01 | D35: Port Harcourt | E35: In-store | F35: Home | G35: Standing Fan | H35: C1089 | I35: Returning | J35: 1 | K35: 58000 | L35: 0.15 | M35: 49300 | N35: 39000 | O35: No | P35: Bola
A36: 100035 | B36: 46076 | C36: KN-01 | D36: Kano | E36: In-store | F36: Accessories | G36: Backpack | H36: C1048 | I36: Returning | J36: 25 | K36: 28000 | L36: 0.05 | M36: 665000 | N36: 16000 | O36: No | P36: Ibrahim
A37: 100036 | B37: 46076 | C37: KN-01 | D37: Kano | E37: In-store | F37: Electronics | G37: Earbuds | H37: C1056 | I37: New | J37: 2 | K37: 32000 | L37: 0.05 | M37: 60800 | N37: 19000 | O37: Yes | P37: Bola
A38: 100037 | B38: 46124 | C38: AB-01 | D38: Abuja | E38: In-store | F38: Accessories | G38: Backpack | H38: C1036 | I38: New | J38: 2 | K38: 28000 | L38: 0 | M38: 56000 | N38: 16000 | O38: No | P38: Grace
A39: 100038 | B39: 46037 | C39: KN-01 | D39: Kano | E39: Online | F39: Electronics | G39: Earbuds | H39: C1138 | I39: Returning | J39: 2 | K39: 32000 | L39: 0 | M39: 64000 | N39: 19000 | O39: No | P39: Aisha
A40: 100039 | B40: 46116 | C40: AB-02 | D40: Abuja | E40: Online | F40: Accessories | G40: USB Cable | H40: C1044 | I40: New | J40: 3 | K40: 6500 | L40: 0.1 | M40: 17550 | N40: 2200 | O40: No | P40: Grace
...

Sheet in
A1: Transaction_ID | B1: Date | C1: Store_ID | D1: State | E1: Channel | F1: Product_Category | G1: Product | H1: Customer_ID | I1: Customer_Type | J1: Units | K1: Unit_Price_NGN | L1: Discount_Pct | M1: Revenue_Reported_NGN | N1: Cost_Per_Unit_NGN | O1: Return_Flag | P1: Sales_Rep | Q1: Q | S1: S | T1: T | U1: u | V1: V | W1: w
A2: 100001 | B2: 46167 | C2: AB-02 | D2: Abuja | E2: WhatsApp | F2: Home | G2: Standing Fan | H2: C1141 | I2: New | J2: 1 | K2: 58000 | L2: 0 | M2: 58000 | O2: No | P2: Chinedu | Q2: {=IF(N2="",_xlfn.XLOOKUP(1,($G$2:$G$433=G2)*($N$2:$N$433<>""),$N$2:$N$433),"")} -> 39000 | R2: =J2*K2*(1-L2) -> 58000 | S2: =IF(M2<>J2*K2*(1-L2),"Mismatch","Match") -> Match | V2: =M2-(J2*N2) -> 58000 | W2: =J2*K2*(1-L2) -> 58000 | X2: =W2-(J2*N2) -> 58000 | Y2: =M2-(J2*N2) -> 58000 | Z2: =SUM(Y2:Y433) -> 16617270 | AA2: =W2-(J2*N2) -> 58000
A3: 100002 | B3: 46129 | C3: LG-01 | D3: Lagos | E3: WhatsApp | F3: Electronics | G3: Smartphone | H3: C1083 | I3: Returning | J3: 5 | K3: 165000 | L3: 0.05 | M3: 627000 | N3: 112000 | O3: No | P3: Kemi | Q3: =COUNTIF($A$2:$A$433,A3)>1 -> FALSE | R3: =J3*K3*(1-L3) -> 783750 | S3: =IF(M3<>J3*K3*(1-L3),"Mismatch","Match") -> Mismatch | T3: =M3-(J3*K3*(1-L3)) -> -156750 | U3: =IF(AND(M3<>J3*K3*(1-L3),M3=J3*K3*(1-L3)*80%),"20% pattern","Other mismatch") -> 20% pattern | V3: =M3-(J3*N3) -> 67000 | W3: =J3*K3*(1-L3) -> 783750 | X3: =W3-(J3*N3) -> 223750 | Y3: =M3-(J3*N3) -> 67000 | AA3: =W2-(J2*N2) -> 58000
A4: 100003 | B4: 46079 | C4: AB-01 | D4: Abuja | E4: WhatsApp | F4: Electronics | G4: Earbuds | H4: C1029 | I4: Returning | J4: 3 | K4: 32000 | L4: 0.2 | M4: 76800 | N4: 19000 | O4: No | P4: Chinedu | Q4: =COUNTIF($A$2:$A$433,A4)>1 -> FALSE | R4: =J4*K4*(1-L4) -> 76800 | S4: =IF(M4<>J4*K4*(1-L4),"Mismatch","Match") -> Match | V4: =M4-(J4*N4) -> 19800 | W4: =J4*K4*(1-L4) -> 76800 | X4: =W4-(J4*N4) -> 19800 | Y4: =M4-(J4*N4) -> 19800 | Z4: =COUNTIF(F2:F433,"Accessory") -> 1
A5: 100004 | B5: 46182 | C5: KN-01 | D5: Kano | E5: Online | F5: Electronics | G5: Power Bank | H5: C1082 | I5: Returning | J5: 4 | K5: 26000 | L5: 0 | M5: 104000 | N5: 15000 | O5: No | P5: Grace | Q5: =COUNTIF($A$2:$A$433,A5)>1 -> FALSE | R5: =J5*K5*(1-L5) -> 104000 | S5: =IF(M5<>J5*K5*(1-L5),"Mismatch","Match") -> Match | V5: =M5-(J5*N5) -> 44000 | W5: =J5*K5*(1-L5) -> 104000 | X5: =W5-(J5*N5) -> 44000 | Y5: =M5-(J5*N5) -> 44000
A6: 100005 | B6: 46172 | C6: LG-01 | D6: Lagos | E6: Online | F6: Electronics | G6: Smartphone | H6: C1180 | I6: Returning | J6: 1 | K6: 165000 | L6: 0.05 | M6: 156750 | N6: 112000 | O6: No | P6: Chinedu | Q6: =COUNTIF($A$2:$A$433,A6)>1 -> FALSE | R6: =J6*K6*(1-L6) -> 156750 | S6: =IF(M6<>J6*K6*(1-L6),"Mismatch","Match") -> Match | V6: =M6-(J6*N6) -> 44750 | W6: =J6*K6*(1-L6) -> 156750 | X6: =W6-(J6*N6) -> 44750 | Y6: =M6-(J6*N6) -> 44750 | Z6: =COUNTIF(F2:F421,"Accessories") -> 106
A7: 100006 | B7: 46238 | C7: LG-02 | D7: Lagos | E7: In-store | F7: Accessories | G7: USB Cable | H7: C1161 | I7: Returning | J7: 3 | K7: 6500 | L7: 0.1 | M7: 17550 | N7: 2200 | O7: No | P7: Bola | Q7: =COUNTIF($A$2:$A$433,A7)>1 -> FALSE | S7: =IF(M7<>J7*K7*(1-L7),"Mismatch","Match") -> Match | V7: =M7-(J7*N7) -> 10950 | W7: =J7*K7*(1-L7) -> 17550 | X7: =W7-(J7*N7) -> 10950 | Y7: =M7-(J7*N7) -> 10950
A8: 100007 | B8: 46090 | C8: LG-01 | D8: Lagos | E8: In-store | F8: Electronics | G8: Power Bank | H8: C1007 | I8: New | J8: 3 | K8: 26000 | L8: 0.1 | M8: 70200 | N8: 15000 | O8: No | P8: Chinedu | Q8: =COUNTIF($A$2:$A$433,A8)>1 -> FALSE | S8: =IF(M8<>J8*K8*(1-L8),"Mismatch","Match") -> Match | V8: =M8-(J8*N8) -> 25200 | W8: =J8*K8*(1-L8) -> 70200 | X8: =W8-(J8*N8) -> 25200 | Y8: =M8-(J8*N8) -> 25200
A9: 100008 | B9: 46229 | C9: KN-01 | D9: Kano | E9: Online | F9: Electronics | G9: Smartphone | H9: C1051 | I9: Returning | J9: 5 | K9: 165000 | L9: 0.05 | M9: 783750 | N9: 112000 | O9: No | P9: Kemi | Q9: =COUNTIF($A$2:$A$433,A9)>1 -> FALSE | S9: =IF(M9<>J9*K9*(1-L9),"Mismatch","Match") -> Match | V9: =M9-(J9*N9) -> 223750 | W9: =J9*K9*(1-L9) -> 783750 | X9: =W9-(J9*N9) -> 223750 | Y9: =M9-(J9*N9) -> 223750
A10: 100009 | B10: 46028 | C10: IB-01 | D10: Ibadan | E10: In-store | F10: Home | G10: Blender | H10: C1111 | I10: Returning | J10: 3 | K10: 42000 | L10: 0.15 | M10: 107100 | N10: 28000 | O10: No | P10: Fatima | Q10: =COUNTIF($A$2:$A$433,A10)>1 -> FALSE | S10: =IF(M10<>J10*K10*(1-L10),"Mismatch","Match") -> Match | V10: =M10-(J10*N10) -> 23100 | W10: =J10*K10*(1-L10) -> 107100 | X10: =W10-(J10*N10) -> 23100 | Y10: =M10-(J10*N10) -> 23100
A11: 100010 | B11: 46248 | C11: PH-01 | D11: Port Harcourt | E11: In-store | F11: Electronics | G11: Smartphone | H11: C1153 | I11: Returning | J11: 1 | K11: 165000 | L11: 0 | M11: 165000 | N11: 112000 | O11: No | P11: David | Q11: =COUNTIF($A$2:$A$433,A11)>1 -> FALSE | S11: =IF(M11<>J11*K11*(1-L11),"Mismatch","Match") -> Match | V11: =M11-(J11*N11) -> 53000 | W11: =J11*K11*(1-L11) -> 165000 | X11: =W11-(J11*N11) -> 53000 | Y11: =M11-(J11*N11) -> 53000
A12: 100011 | B12: 46200 | C12: LG-01 | D12: Lagos | E12: In-store | F12: Electronics | G12: Earbuds | H12: C1059 | I12: Returning | J12: 1 | K12: 32000 | L12: 0 | M12: 32000 | N12: 19000 | O12: No | P12: David | Q12: =COUNTIF($A$2:$A$433,A12)>1 -> FALSE | S12: =IF(M12<>J12*K12*(1-L12),"Mismatch","Match") -> Match | V12: =M12-(J12*N12) -> 13000 | W12: =J12*K12*(1-L12) -> 32000 | X12: =W12-(J12*N12) -> 13000 | Y12: =M12-(J12*N12) -> 13000
A13: 100012 | B13: 46120 | C13: KN-01 | D13: Kano | E13: Online | F13: Accessories | G13: Phone Case | H13: C1028 | I13: New | J13: 1 | K13: 9000 | L13: 0 | M13: 9000 | N13: 3500 | O13: No | P13: David | Q13: =COUNTIF($A$2:$A$433,A13)>1 -> FALSE | S13: =IF(M13<>J13*K13*(1-L13),"Mismatch","Match") -> Match | V13: =M13-(J13*N13) -> 5500 | W13: =J13*K13*(1-L13) -> 9000 | X13: =W13-(J13*N13) -> 5500 | Y13: =M13-(J13*N13) -> 5500
A14: 100013 | B14: 46153 | C14: IB-01 | D14: Ibadan | E14: In-store | F14: Home | G14: Electric Kettle | H14: C1192 | I14: New | J14: 2 | K14: 24000 | L14: 0 | M14: 48000 | N14: 15000 | O14: No | P14: Ibrahim | Q14: =COUNTIF($A$2:$A$433,A14)>1 -> FALSE | S14: =IF(M14<>J14*K14*(1-L14),"Mismatch","Match") -> Match | V14: =M14-(J14*N14) -> 18000 | W14: =J14*K14*(1-L14) -> 48000 | X14: =W14-(J14*N14) -> 18000 | Y14: =M14-(J14*N14) -> 18000
A15: 100014 | B15: 46195 | C15: AB-02 | D15: Abuja | E15: WhatsApp | F15: Accessories | G15: Backpack | H15: C1022 | I15: Returning | J15: 2 | K15: 28000 | L15: 0.25 | M15: 42000 | O15: No | P15: Fatima | Q15: {=IF(N15="",_xlfn.XLOOKUP(1,($G$2:$G$433=G15)*($N$2:$N$433<>""),$N$2:$N$433),"")} -> 16000 | S15: =IF(M15<>J15*K15*(1-L15),"Mismatch","Match") -> Match | V15: =M15-(J15*N15) -> 42000 | W15: =J15*K15*(1-L15) -> 42000 | X15: =W15-(J15*N15) -> 42000 | Y15: =M15-(J15*N15) -> 42000
A16: 100015 | B16: 46031 | C16: PH-01 | D16: Port Harcourt | E16: In-store | F16: Electronics | G16: Smartphone | H16: C1084 | I16: New | J16: 2 | K16: 165000 | L16: 0 | M16: 330000 | N16: 112000 | O16: No | P16: Grace | Q16: =COUNTIF($A$2:$A$433,A16)>1 -> FALSE | S16: =IF(M16<>J16*K16*(1-L16),"Mismatch","Match") -> Match | V16: =M16-(J16*N16) -> 106000 | W16: =J16*K16*(1-L16) -> 330000 | X16: =W16-(J16*N16) -> 106000 | Y16: =M16-(J16*N16) -> 106000
A17: 100016 | B17: 46228 | C17: LG-02 | D17: Lagos | E17: Online | F17: Accessories | G17: USB Cable | H17: C1123 | I17: New | J17: 1 | K17: 6500 | L17: 0.1 | M17: 4680 | N17: 2200 | O17: No | P17: Kemi | Q17: =COUNTIF($A$2:$A$433,A17)>1 -> FALSE | S17: =IF(M17<>J17*K17*(1-L17),"Mismatch","Match") -> Mismatch | T17: =M17-(J17*K17*(1-L17)) -> -1170 | U17: =IF(AND(M17<>J17*K17*(1-L17),M17=J17*K17*(1-L17)*80%),"20% pattern","Other mismatch") -> 20% pattern | V17: =M17-(J17*N17) -> 2480 | W17: =J17*K17*(1-L17) -> 5850 | X17: =W17-(J17*N17) -> 3650 | Y17: =M17-(J17*N17) -> 2480
A18: 100017 | B18: 46032 | C18: KN-01 | D18: Kano | E18: WhatsApp | F18: Home | G18: Blender | H18: C1134 | I18: New | J18: 2 | K18: 42000 | L18: 0 | M18: 84000 | N18: 28000 | O18: No | P18: Ibrahim | Q18: =COUNTIF($A$2:$A$433,A18)>1 -> FALSE | S18: =IF(M18<>J18*K18*(1-L18),"Mismatch","Match") -> Match | V18: =M18-(J18*N18) -> 28000 | W18: =J18*K18*(1-L18) -> 84000 | X18: =W18-(J18*N18) -> 28000 | Y18: =M18-(J18*N18) -> 28000
A19: 100018 | B19: 46141 | C19: PH-01 | D19: Port Harcourt | E19: In-store | F19: Accessories | G19: USB Cable | H19: C1100 | I19: Returning | J19: 22 | K19: 6500 | L19: 0.15 | M19: 121550 | N19: 2200 | O19: No | P19: Kemi | Q19: =COUNTIF($A$2:$A$433,A19)>1 -> FALSE | S19: =IF(M19<>J19*K19*(1-L19),"Mismatch","Match") -> Match | V19: =M19-(J19*N19) -> 73150 | W19: =J19*K19*(1-L19) -> 121550 | X19: =W19-(J19*N19) -> 73150 | Y19: =M19-(J19*N19) -> 73150
A20: 100019 | B20: 46148 | C20: LG-01 | D20: Lagos | E20: In-store | F20: Electronics | G20: Power Bank | H20: C1189 | I20: Returning | J20: 1 | K20: 26000 | L20: 0.15 | M20: 22100 | N20: 15000 | O20: No | P20: Bola | Q20: =COUNTIF($A$2:$A$433,A20)>1 -> FALSE | S20: =IF(M20<>J20*K20*(1-L20),"Mismatch","Match") -> Match | V20: =M20-(J20*N20) -> 7100 | W20: =J20*K20*(1-L20) -> 22100 | X20: =W20-(J20*N20) -> 7100 | Y20: =M20-(J20*N20) -> 7100
A21: 100020 | B21: 46131 | C21: AB-02 | D21: Abuja | E21: In-store | F21: Electronics | G21: Power Bank | H21: C1050 | I21: Returning | J21: 1 | K21: 26000 | L21: 0.25 | M21: 19500 | O21: No | P21: Ibrahim | Q21: {=IF(N21="",_xlfn.XLOOKUP(1,($G$2:$G$433=G21)*($N$2:$N$433<>""),$N$2:$N$433),"")} -> 15000 | R21: =SUBTOTAL(109,Q2:Q433) -> 921600 | S21: =IF(M21<>J21*K21*(1-L21),"Mismatch","Match") -> Match | V21: =M21-(J21*N21) -> 19500 | W21: =J21*K21*(1-L21) -> 19500 | X21: =W21-(J21*N21) -> 19500 | Y21: =M21-(J21*N21) -> 19500
A22: 100021 | B22: 46148 | C22: AB-02 | D22: Abuja | E22: WhatsApp | F22: Electronics | G22: Power Bank | H22: C1184 | I22: New | J22: 1 | K22: 26000 | L22: 0 | M22: 26000 | N22: 15000 | O22: No | P22: Kemi | Q22: =COUNTIF($A$2:$A$433,A22)>1 -> FALSE | S22: =IF(M22<>J22*K22*(1-L22),"Mismatch","Match") -> Match | V22: =M22-(J22*N22) -> 11000 | W22: =J22*K22*(1-L22) -> 26000 | X22: =W22-(J22*N22) -> 11000 | Y22: =M22-(J22*N22) -> 11000
A23: 100022 | B23: 46033 | C23: IB-01 | D23: Ibadan | E23: WhatsApp | F23: Accessories | G23: Backpack | H23: C1022 | I23: New | J23: 1 | K23: 28000 | L23: 0.05 | M23: 26600 | N23: 16000 | O23: No | P23: Bola | Q23: =COUNTIF($A$2:$A$433,A23)>1 -> FALSE | S23: =IF(M23<>J23*K23*(1-L23),"Mismatch","Match") -> Match | V23: =M23-(J23*N23) -> 10600 | W23: =J23*K23*(1-L23) -> 26600 | X23: =W23-(J23*N23) -> 10600 | Y23: =M23-(J23*N23) -> 10600
A24: 100023 | B24: 46052 | C24: AB-01 | D24: Abuja | E24: Online | F24: Electronics | G24: Earbuds | H24: C1004 | I24: Returning | J24: 1 | K24: 32000 | L24: 0.15 | M24: 27200 | N24: 19000 | O24: No | P24: David | Q24: =COUNTIF($A$2:$A$433,A24)>1 -> FALSE | S24: =IF(M24<>J24*K24*(1-L24),"Mismatch","Match") -> Match | V24: =M24-(J24*N24) -> 8200 | W24: =J24*K24*(1-L24) -> 27200 | X24: =W24-(J24*N24) -> 8200 | Y24: =M24-(J24*N24) -> 8200
A25: 100024 | B25: 46150 | C25: AB-01 | D25: Abuja | E25: In-store | F25: Home | G25: Standing Fan | H25: C1034 | I25: New | J25: 2 | K25: 58000 | L25: 0.2 | M25: 92800 | O25: Yes | P25: Grace | Q25: {=IF(N25="",_xlfn.XLOOKUP(1,($G$2:$G$433=G25)*($N$2:$N$433<>""),$N$2:$N$433),"")} -> 39000 | S25: =IF(M25<>J25*K25*(1-L25),"Mismatch","Match") -> Match | V25: =M25-(J25*N25) -> 92800 | W25: =J25*K25*(1-L25) -> 92800 | X25: =W25-(J25*N25) -> 92800 | Y25: =M25-(J25*N25) -> 92800
A26: 100025 | B26: 46027 | C26: KN-01 | D26: Kano | E26: In-store | F26: Home | G26: Standing Fan | H26: C1164 | I26: Returning | J26: 5 | K26: 58000 | L26: 0.05 | M26: 275500 | N26: 39000 | O26: No | P26: David | Q26: =COUNTIF($A$2:$A$433,A26)>1 -> FALSE | S26: =IF(M26<>J26*K26*(1-L26),"Mismatch","Match") -> Match | V26: =M26-(J26*N26) -> 80500 | W26: =J26*K26*(1-L26) -> 275500 | X26: =W26-(J26*N26) -> 80500 | Y26: =M26-(J26*N26) -> 80500
A27: 100026 | B27: 46203 | C27: IB-01 | D27: Ibadan | E27: In-store | F27: Accessories | G27: Phone Case | H27: C1155 | I27: Returning | J27: 2 | K27: 9000 | L27: 0.1 | M27: 16200 | O27: No | P27: Chinedu | Q27: {=IF(N27="",_xlfn.XLOOKUP(1,($G$2:$G$433=G27)*($N$2:$N$433<>""),$N$2:$N$433),"")} -> 3500 | S27: =IF(M27<>J27*K27*(1-L27),"Mismatch","Match") -> Match | V27: =M27-(J27*N27) -> 16200 | W27: =J27*K27*(1-L27) -> 16200 | X27: =W27-(J27*N27) -> 16200 | Y27: =M27-(J27*N27) -> 16200
A28: 100027 | B28: 46142 | C28: KN-01 | D28: Kano | E28: WhatsApp | F28: Home | G28: Standing Fan | H28: C1073 | I28: New | J28: 4 | K28: 58000 | L28: 0.05 | M28: 220400 | N28: 39000 | O28: No | P28: David | Q28: =COUNTIF($A$2:$A$433,A28)>1 -> FALSE | S28: =IF(M28<>J28*K28*(1-L28),"Mismatch","Match") -> Match | V28: =M28-(J28*N28) -> 64400 | W28: =J28*K28*(1-L28) -> 220400 | X28: =W28-(J28*N28) -> 64400 | Y28: =M28-(J28*N28) -> 64400
A29: 100028 | B29: 46156 | C29: AB-01 | D29: Abuja | E29: Online | F29: Electronics | G29: Power Bank | H29: C1136 | I29: Returning | J29: 22 | K29: 26000 | L29: 0.25 | M29: 429000 | N29: 15000 | O29: No | P29: Bola | Q29: =COUNTIF($A$2:$A$433,A29)>1 -> FALSE | S29: =IF(M29<>J29*K29*(1-L29),"Mismatch","Match") -> Match | V29: =M29-(J29*N29) -> 99000 | W29: =J29*K29*(1-L29) -> 429000 | X29: =W29-(J29*N29) -> 99000 | Y29: =M29-(J29*N29) -> 99000
A30: 100029 | B30: 46103 | C30: AB-01 | D30: Abuja | E30: In-store | F30: Home | G30: Standing Fan | H30: C1173 | I30: Returning | J30: 5 | K30: 58000 | L30: 0.1 | M30: 261000 | O30: No | P30: Chinedu | Q30: {=IF(N30="",_xlfn.XLOOKUP(1,($G$2:$G$433=G30)*($N$2:$N$433<>""),$N$2:$N$433),"")} -> 39000 | S30: =IF(M30<>J30*K30*(1-L30),"Mismatch","Match") -> Match | V30: =M30-(J30*N30) -> 261000 | W30: =J30*K30*(1-L30) -> 261000 | X30: =W30-(J30*N30) -> 261000 | Y30: =M30-(J30*N30) -> 261000
A31: 100030 | B31: 46209 | C31: KN-01 | D31: Kano | E31: Online | F31: Electronics | G31: Power Bank | H31: C1071 | I31: New | J31: 1 | K31: 26000 | L31: 0.05 | M31: 24700 | N31: 15000 | O31: No | P31: David | Q31: =COUNTIF($A$2:$A$433,A31)>1 -> FALSE | S31: =IF(M31<>J31*K31*(1-L31),"Mismatch","Match") -> Match | V31: =M31-(J31*N31) -> 9700 | W31: =J31*K31*(1-L31) -> 24700 | X31: =W31-(J31*N31) -> 9700 | Y31: =M31-(J31*N31) -> 9700
A32: 100031 | B32: 46182 | C32: AB-01 | D32: Abuja | E32: In-store | F32: Home | G32: Standing Fan | H32: C1047 | I32: New | J32: 2 | K32: 58000 | L32: 0.15 | M32: 98600 | N32: 39000 | O32: No | P32: Aisha | Q32: =COUNTIF($A$2:$A$433,A32)>1 -> FALSE | S32: =IF(M32<>J32*K32*(1-L32),"Mismatch","Match") -> Match | V32: =M32-(J32*N32) -> 20600 | W32: =J32*K32*(1-L32) -> 98600 | X32: =W32-(J32*N32) -> 20600 | Y32: =M32-(J32*N32) -> 20600
A33: 100032 | B33: 46109 | C33: PH-01 | D33: Port Harcourt | E33: Online | F33: Home | G33: Electric Kettle | H33: C1051 | I33: New | J33: 1 | K33: 24000 | L33: 0.05 | M33: 22800 | N33: 15000 | O33: No | P33: Kemi | Q33: =COUNTIF($A$2:$A$433,A33)>1 -> FALSE | S33: =IF(M33<>J33*K33*(1-L33),"Mismatch","Match") -> Match | V33: =M33-(J33*N33) -> 7800 | W33: =J33*K33*(1-L33) -> 22800 | X33: =W33-(J33*N33) -> 7800 | Y33: =M33-(J33*N33) -> 7800
A34: 100033 | B34: 46152 | C34: LG-01 | D34: Lagos | E34: In-store | F34: Home | G34: Standing Fan | H34: C1094 | I34: New | J34: 3 | K34: 58000 | L34: 0 | M34: 174000 | N34: 39000 | O34: No | P34: Aisha | Q34: =COUNTIF($A$2:$A$433,A34)>1 -> FALSE | S34: =IF(M34<>J34*K34*(1-L34),"Mismatch","Match") -> Match | V34: =M34-(J34*N34) -> 57000 | W34: =J34*K34*(1-L34) -> 174000 | X34: =W34-(J34*N34) -> 57000 | Y34: =M34-(J34*N34) -> 57000
A35: 100034 | B35: 46157 | C35: PH-01 | D35: Port Harcourt | E35: In-store | F35: Home | G35: Standing Fan | H35: C1089 | I35: Returning | J35: 1 | K35: 58000 | L35: 0.15 | M35: 49300 | N35: 39000 | O35: No | P35: Bola | Q35: =COUNTIF($A$2:$A$433,A35)>1 -> FALSE | S35: =IF(M35<>J35*K35*(1-L35),"Mismatch","Match") -> Match | V35: =M35-(J35*N35) -> 10300 | W35: =J35*K35*(1-L35) -> 49300 | X35: =W35-(J35*N35) -> 10300 | Y35: =M35-(J35*N35) -> 10300
A36: 100035 | B36: 46076 | C36: KN-01 | D36: Kano | E36: In-store | F36: Accessories | G36: Backpack | H36: C1048 | I36: Returning | J36: 25 | K36: 28000 | L36: 0.05 | M36: 665000 | N36: 16000 | O36: No | P36: Ibrahim | Q36: =COUNTIF($A$2:$A$433,A36)>1 -> FALSE | S36: =IF(M36<>J36*K36*(1-L36),"Mismatch","Match") -> Match | V36: =M36-(J36*N36) -> 265000 | W36: =J36*K36*(1-L36) -> 665000 | X36: =W36-(J36*N36) -> 265000 | Y36: =M36-(J36*N36) -> 265000
A37: 100036 | B37: 46076 | C37: KN-01 | D37: Kano | E37: In-store | F37: Electronics | G37: Earbuds | H37: C1056 | I37: New | J37: 2 | K37: 32000 | L37: 0.05 | M37: 60800 | N37: 19000 | O37: Yes | P37: Bola | Q37: =COUNTIF($A$2:$A$433,A37)>1 -> FALSE | S37: =IF(M37<>J37*K37*(1-L37),"Mismatch","Match") -> Match | V37: =M37-(J37*N37) -> 22800 | W37: =J37*K37*(1-L37) -> 60800 | X37: =W37-(J37*N37) -> 22800 | Y37: =M37-(J37*N37) -> 22800
A38: 100037 | B38: 46124 | C38: AB-01 | D38: Abuja | E38: In-store | F38: Accessories | G38: Backpack | H38: C1036 | I38: New | J38: 2 | K38: 28000 | L38: 0 | M38: 56000 | N38: 16000 | O38: No | P38: Grace | Q38: =COUNTIF($A$2:$A$433,A38)>1 -> FALSE | S38: =IF(M38<>J38*K38*(1-L38),"Mismatch","Match") -> Match | V38: =M38-(J38*N38) -> 24000 | W38: =J38*K38*(1-L38) -> 56000 | X38: =W38-(J38*N38) -> 24000 | Y38: =M38-(J38*N38) -> 24000
A39: 100038 | B39: 46037 | C39: KN-01 | D39: Kano | E39: Online | F39: Electronics | G39: Earbuds | H39: C1138 | I39: Returning | J39: 2 | K39: 32000 | L39: 0 | M39: 64000 | N39: 19000 | O39: No | P39: Aisha | Q39: =COUNTIF($A$2:$A$433,A39)>1 -> FALSE | S39: =IF(M39<>J39*K39*(1-L39),"Mismatch","Match") -> Match | V39: =M39-(J39*N39) -> 26000 | W39: =J39*K39*(1-L39) -> 64000 | X39: =W39-(J39*N39) -> 26000 | Y39: =M39-(J39*N39) -> 26000
A40: 100039 | B40: 46116 | C40: AB-02 | D40: Abuja | E40: Online | F40: Accessories | G40: USB Cable | H40: C1044 | I40: New | J40: 3 | K40: 6500 | L40: 0.1 | M40: 17550 | N40: 2200 | O40: No | P40: Grace | Q40: =COUNTIF($A$2:$A$433,A40)>1 -> FALSE | S40: =IF(M40<>J40*K40*(1-L40),"Mismatch","Match") -> Match | V40: =M40-(J40*N40) -> 10950 | W40: =J40*K40*(1-L40) -> 17550 | X40: =W40-(J40*N40) -> 10950 | Y40: =M40-(J40*N40) -> 10950
...
